Workbook

Sheet Sheet8
B1: First Name | H1: Email | AU1: Filter Rows to Merge
A2: 45753.909 | B2: Brian | C2: Davids | D2: 23388 | E2: davidsbg@bc.edu | F2: bzachdavids@gmail.com | G2: College/Secondary email: | H2: =IF(G2="College/Secondary email:",E2,F2) -> davidsbg@bc.edu | I2: Glenn Dale | J2: Analyst | K2: +13015182003 | L2: Male | M2: Spring 2024 | N2: 2027 | O2: North America | P2: Boston (U.S.) | Q2: Yes | R2: Long Horizon Partners | S2: Virtual | T2: Private Equity | U2: 1 | V2: N/A | W2: PWC | X2: New York, NY | Y2: Consulting | Z2: 1 | AA2: N/A | AB2: Evercore | AC2: New York, NY | AD2: Investment Banking | AE2: 1 | AF2: N/A | AG2: N/A | AH2: Boston College | AI2: Newton, MA | AJ2: Target | AK2: 3.7 | AL2: Finance and Business Analytics | AM2: 2027 | AN2: MLT, SEO | AO2: https://drive.google.com/open?id=1XWClHCwCx5aNJniGdFhaFayO5decO7qu | AP2: Investment Banking, Private Equity, Venture Capital, Hedge Funds | AQ2: Advent, DE Shaw, Warburg | AR2: Pursuing Banking but interested in Public and Private Markets Investing for After Analyst Years | AT2: Analyst
A3: 45753.91 | B3: EJ | C3: Ibhawoh | D3: 23043 | E3: ibhawoha@mcmaster.ca | F3: ejiyeibhawoh@gmail.com | G3: College/Secondary email: | H3: =IF(G3="College/Secondary email:",E3,F3) -> ibhawoha@mcmaster.ca | I3: Hamilton | J3: Analyst | K3: 19057450150 | L3: Male | M3: Fall 2022 | N3: 2026 | O3: North America | P3: Toronto (Canada) | Q3: Yes | R3: BDC | S3: Toronto | T3: Venture Capital | U3: N/A | V3: N/A | W3: CIBC | X3: Toronto | Y3: Sales & Trading | Z3: N/A | AA3: N/A | AB3: RBC | AC3: Toronto | AD3: Investment Banking | AE3: N/A | AF3: N/A | AG3: N/A | AH3: McMaster University | AI3: Hamilton | AJ3: Non-target | AK3: 4 | AL3: Commerce | AM3: 2026 | AN3: Bridging the Gap | AO3: https://drive.google.com/open?id=1iSck4HjUOK-tMmh3tgnAAAmBNI8Eytqq | AP3: Investment Banking, Private Equity, Asset Management | AQ3: JP Morgan, Goldman Sachs, Morgan Stanley | AR3: Any American Investment Banking Position | AT3: Analyst
A4: 45753.911 | B4: Allegra | C4: Nshuti | D4: 23260 | E4: an3161@columbia.edu | F4: allegranshuti123@gmail.com | G4: Personal email | H4: =IF(G4="College/Secondary email:",E4,F4) -> allegranshuti123@gmail.com | I4: Kigali | J4: Community Member | K4: 19173851412 | L4: Female | M4: Spring 2023 | N4: 2026 | O4: North America | P4: New York City (U.S.) | Q4: Yes | R4: Rwanda Development Board | S4: Kigali | T4: Venture Capital | U4: 1 | V4: Na | W4: Morgan stanley | X4: New York | Y4: Private wealth | Z4: 1 | AA4: Na | AB4: Morgan stanley | AC4: New York | AD4: Sales and Trading | AE4: 0 | AF4: Na | AG4: Na | AH4: Columbia University | AI4: New york | AJ4: Target | AK4: 3.7 | AL4: Economics | AM4: 2026 | AN4: None | AO4: https://drive.google.com/open?id=10Dcy0cDIANA1n3UOdPrdOCwxXztrh1VS | AP4: Sales and Trading, Private Equity, Venture Capital, Hedge Funds | AQ4: Na | AR4: Na | AT4: Community Member
A5: 45753.911 | B5: Keyonte’ | C5: Doughty | D5: BLK - 23311 | E5: keyonte.d.doughty@vanderbilt.edu | F5: kd.doughty66@gmail.com | G5: Personal email | H5: =IF(G5="College/Secondary email:",E5,F5) -> kd.doughty66@gmail.com | I5: Tuscaloosa, AL | J5: Senior analyst | K5: 2058726413 | L5: Male | M5: Spring 2024 | N5: 2025 | O5: North America | P5: N/A | Q5: Yes | R5: Congressional Black Caucus Foundation | S5: Washington, D.C. | T5: Government | U5: N/A | V5: N/A | W5: Affiliated Managers Group | X5: Boston, MA | Y5: Asset Management | Z5: N/A | AA5: N/A | AB5: Citigroup | AC5: New York, New York | AD5: Sales & Trading | AE5: 1 | AF5: N/A | AG5: Citi | AH5: Vanderbilt University | AI5: Nashville, TN | AJ5: Target | AK5: 3.63 | AL5: Human & Organizational Development, Political Science | AM5: 2025 | AN5: SEO | AO5: https://drive.google.com/open?id=1AWIuUcQF6mEJKQCCW_AbEXIbW1fEi7WZ | AP5: Investment Banking, Sales and Trading, Private Equity, Real Estate, Legal, Risk & Compliance | AQ5: Bain & Capital, Carlyle Group, J.P. Morgan, Goldman Sachs, TD Cowen | AR5: Interested in going to PE post S&T | AT5: Alumni (only select if you are graduated/graduating this year)
A6: 45753.912 | B6: Malik | C6: Denney | D6: BLK-23146 | E6: Malik.Denney@bison.Howard.edu | F6: Malik.denney1@gmail.con | G6: Personal email | H6: =IF(G6="College/Secondary email:",E6,F6) -> Malik.denney1@gmail.con | I6: Atlanta | J6: Analyst | K6: 4046838903 | L6: Male | M6: Spring 2023 | N6: 2026 | O6: North America | P6: N/A | Q6: Yes | R6: Deloittw | S6: Atlanta, GA | T6: Consulting | U6: 2 | V6: Higher pay | W6: Permira Advisors | X6: New York, New York | Y6: Private equity | Z6: 3 | AA6: Prestige | AB6: BMO Capital Markets | AC6: New York, NY | AD6: Investment Banking | AE6: 1 | AF6: Na | AG6: Na | AH6: Howard University | AI6: Washington D.C | AJ6: Non-target | AK6: 3.3 | AL6: Finance | AM6: 2026 | AN6: Huig | AO6: https://drive.google.com/open?id=1lMpAUbh_PZNJoJMd4p5HEoGGoWu_6ITj | AP6: Investment Banking | AQ6: Evercore | AT6: Education Pathways (IB, AWM, or PE)
A7: 45753.913 | B7: Glenn | C7: Osemeha | D7: 23036 | E7: Gosemeha@wesleyan.edu | F7: gosemeha@gmail.com | G7: Personal email | H7: =IF(G7="College/Secondary email:",E7,F7) -> gosemeha@gmail.com | I7: West Orange | J7: Community Member | K7: +19739815898 | L7: Male | M7: Spring 2023 | N7: 2026 | O7: North America | P7: Boston (U.S.) | Q7: Yes | R7: Alyeska Investment group | S7: Chicago IL | T7: Hedgefund | U7: 2 | V7: N/a | W7: TD Securities | X7: New York NY | Y7: Sales and trading | Z7: N/A | AA7: N/A | AB7: N/A | AC7: N/A | AD7: N/A | AE7: N/A | AF7: N/A | AG7: N/A | AH7: Wesleyan University | AI7: Middletown | AJ7: Liberal Arts College, Non-Target School | AK7: 3.4 | AL7: Economics | AM7: 2026 | AN7: SEO | AO7: https://drive.google.com/open?id=1htBzQ4U9JmmsO98nKwZ23co1nEs2PV01 | AP7: Asset Management | AQ7: Citi | AT7: Community Member
A8: 45753.916 | B8: Patrick | C8: Bongo | D8: 24020 | E8: patrick.m.bongo.27@dartmouth.edu | F8: MVOO21032GMAIL.COM | G8: College/Secondary email: | H8: =IF(G8="College/Secondary email:",E8,F8) -> patrick.m.bongo.27@dartmouth.edu | I8: Mombasa | J8: Analyst | K8: +6032668130 | L8: Male | M8: Spring 2024 | N8: 2027 | O8: North America | P8: N/A | Q8: Yes | R8: N/A | S8: N/A | T8: N/A | U8: N/A | V8: N/A | W8: N/A | X8: N/A | Y8: N/A | Z8: N/A | AA8: N/A | AB8: Nomura | AC8: NYC | AD8: Sales & Trading | AE8: 2 | AF8: Preference | AG8: N/A | AH8: Dartmouth College | AI8: Hanover | AJ8: Target | AK8: 3.74 | AL8: Comp Science | AM8: 2027 | AN8: Black Gen Finance | AO8: https://drive.google.com/open?id=16Pz6ikkt1Lbyfoxv_PL_tlhdmij0Vh2w | AP8: Investment Banking, Sales and Trading, Private Equity | AQ8: PE | AR8: PE and any other PE organizations | AT8: Analyst
A9: 45753.916 | B9: Aiden | C9: Nelson | D9: 23353 | E9: anelson02@wesleyan.edu | F9: aidensnelson6@gmail.com | G9: College/Secondary email: | H9: =IF(G9="College/Secondary email:",E9,F9) -> anelson02@wesleyan.edu | I9: Hagerstown | J9: Community Member | K9: 3015733122 | L9: Male | M9: Fall 2024 | N9: 2027 | O9: North America | P9: N/A | Q9: Yes | R9: Clark Construction | S9: Mclean VA | T9: Accounting | U9: N/A | V9: N/A | W9: J.p. morgan Chase | X9: New York, NY | Y9: Securities Services | Z9: N/A | AA9: N/A | AB9: N/A | AC9: N/A | AD9: N/A | AE9: N/A | AF9: N/A | AG9: N/A | AH9: Wesleyan University | AI9: Middletown | AJ9: Liberal Arts College, Non-Target School | AK9: 3.5 | AL9: Econ | AM9: 2027 | AN9: SEO | AO9: https://drive.google.com/open?id=19Q2fe54IpFcNi90QvVWZ1goYYwkfpKQg | AP9: Sales and Trading | AQ9: JP, Citi, MS, GS, WF | AT9: Analyst
A10: 45753.922 | B10: Maya | C10: Lewis | D10: BLK-24102 | E10: mayajlewis@uchicago.edu | F10: mayajasmine05@gmail.com | G10: College/Secondary email: | H10: =IF(G10="College/Secondary email:",E10,F10) -> mayajlewis@uchicago.edu | I10: Burlington, NJ | J10: Analyst | K10: 9083009622 | L10: Female | M10: Fall 2024 | N10: 2028 | O10: North America | P10: N/A | Q10: Yes | R10: N/A | S10: N/A | T10: N/A | U10: N/A | V10: N/A | W10: N/A | X10: N/A | Y10: N/A | Z10: N/A | AA10: N/A | AB10: N/A | AC10: N/A | AD10: N/A | AE10: N/A | AF10: N/A | AG10: N/A | AH10: University of Chicago | AI10: Chicago | AJ10: Target | AK10: 3.3 | AL10: Business Economics & Public Policy | AM10: 2028 | AN10: INROADS, Girls Who Invest, Project Destined | AO10: https://drive.google.com/open?id=1RiHQVITmVo-4QtHRbp2hoX6czBXfkctD | AP10: Sales and Trading, Venture Capital, Hedge Funds, Economic Consulting, Equity Research | AQ10: Nera, US Bank, Cornerstone Research | AT10: Analyst
A11: 45753.923 | B11: Jamari | C11: Myers | D11: BLK - 23372 | E11: jamari_myers@brown.edu | F11: jamari.myers2023@gmail.com | G11: College/Secondary email: | H11: =IF(G11="College/Secondary email:",E11,F11) -> jamari_myers@brown.edu | I11: Mansfield, TX | J11: Analyst | K11: +19789980846 | L11: Male | M11: Spring 2024 | N11: 2027 | O11: North America | P11: N/A | Q11: Yes | R11: Decatur Street Capital | S11: Remote | T11: Private Equity - Search Fund | U11: 3 | V11: This internship was the best fit for what I hoped to gain. | W11: J.P. Morgan | X11: New York, New York | Y11: Investment Banking | Z11: 1 | AA11: N/A | AB11: N/A, J.P. Morgan | AC11: New York, New York | AD11: Investment Banking | AE11: N/A | AF11: N/A | AG11: N/A | AH11: Brown University | AI11: Providence, RI | AJ11: Target | AK11: 3.75 | AL11: Business Economics and Entrepreneurship | AM11: 2027 | AN11: SEO | AO11: https://drive.google.com/open?id=1cvj_Ut2UurUuoFcS8Zx3chzUe28w8nzo | AP11: Investment Banking, Private Equity, Business & Entreprenuership | AQ11: Apollo | AT11: Analyst
A12: 45753.923 | B12: Christela | C12: Bosco | D12: BLK - 23351 | E12: Christelabosco@gmail.com | F12: Christelabosco@gmail.com | G12: Personal email | H12: =IF(G12="College/Secondary email:",E12,F12) -> Christelabosco@gmail.com | I12: Nashville, TN | J12: Roark fellow | K12: 1 | L12: Female | M12: Spring 2024 | N12: 2027 | O12: North America | P12: Atlanta (U.S.) | Q12: Yes | R12: N/A | S12: N/A | T12: N/A | U12: N/A | V12: N/A | W12: N/A | X12: N/A | Y12: N/A | Z12: N/A | AA12: N/A | AB12: N/A | AC12: N/A | AD12: N/A | AE12: N/A | AF12: N/A | AG12: N/A | AH12: University of Tennessee | AI12: Knoxville | AJ12: Non-target | AK12: 4 | AL12: Business | AM12: 2027 | AN12: SEO, Girls Who Invest | AO12: https://drive.google.com/open?id=130pSyXHdOXzXoDZg7PCHxTxFFC30zM46 | AP12: Private Equity, Management Consulting, Real Estate, Legal, Risk & Compliance | AQ12: Blackstone, Ares, Carlyle, KKR | AT12: Community Member
A13: 45753.927 | B13: Matthew | C13: Frazier | D13: BLK-23233 | E13: Mfrazier1@babson.edu | F13: Mkfrazier.edu@gmail.com | G13: Personal email | H13: =IF(G13="College/Secondary email:",E13,F13) -> Mkfrazier.edu@gmail.com | I13: Chicago | J13: Portfolio Manager | K13: +16172299484 | L13: Male | M13: Fall 2023 | N13: 2026 | O13: North America | P13: Boston (U.S.) | Q13: Yes | R13: Evercore | S13: New York City, New York | T13: Equity Research, Sales & Trading | U13: 1 | V13: N/A | W13: Cleardrop Investment | X13: Remote | Y13: Hedge Fund | Z13: 1 | AA13: N/A | AB13: N/A | AC13: N/A | AD13: N/A | AE13: N/A | AF13: N/A | AG13: N/A | AH13: Babson College | AI13: Wellesley, MA | AJ13: Non-target | AK13: 3.73 | AL13: Finance | AM13: 2026 | AN13: MLT, SEO, INROADS | AO13: https://drive.google.com/open?id=1NqojdFJqYC3WoOhaXKdGTluJmPBLgibM | AP13: Investment Banking, Sales and Trading, Private Equity, Asset Management, Management Consulting, Hedge Funds | AQ13: N/A | AR13: N/A | AT13: Community Member
A14: 45753.939 | B14: Steve | C14: Fotso | D14: BLK - 24074 | E14: fotsos@mcmaster.ca | F14: fotsoryan@gmail.com | G14: Personal email | H14: =IF(G14="College/Secondary email:",E14,F14) -> fotsoryan@gmail.com | I14: Hamilton, Canada | J14: Senior analyst | K14: 12265064621 | L14: Male | M14: Fall 2024 | N14: 2026 | O14: North America | P14: Toronto (Canada) | Q14: No | R14: Investment Management Corporation of Ontario (IMCO) | S14: Toronto, Ontario | T14: Asset Managament | U14: N/A | V14: N/A | W14: Toronto Dominion (TD) Bank | X14: Toronto, Ontario | Y14: Compliance | Z14: N/A | AA14: N/A | AB14: N/A | AC14: N/A | AD14: N/A | AE14: N/A | AF14: N/A | AG14: N/A | AH14: McMaster University | AI14: Hamilton, Canada | AJ14: Non-target | AK14: 3.7 | AL14: Finance | AM14: 2026 | AN14: BLK, Investa | AO14: https://drive.google.com/open?id=12TOa85ti3NI1BDLBYA6chnLLNueEtTGS | AP14: Investment Banking, Sales and Trading, Asset Management | AQ14: TD Securities | AT14: Education Pathways (IB, AWM, or PE)
A15: 45753.94 | B15: Madison | C15: Duff | D15: BLK-24131 | E15: madison_duff@brown.edu | F15: munk7@icloud.com | G15: College/Secondary email: | H15: =IF(G15="College/Secondary email:",E15,F15) -> madison_duff@brown.edu | I15: Grosse Pointe Farms, MI | J15: Community Member | K15: +13139104525 | L15: Female | M15: Fall 2024 | N15: 2027 | O15: North America | P15: Boston (U.S.) | Q15: Yes | R15: N/A | S15: N/A | T15: N/A | U15: N/A | V15: N/A | W15: Research through Brown University | X15: Providence, RI | Y15: Economic and Public Policy Research | Z15: N/A | AA15: N/A | AB15: N/A | AC15: N/A | AD15: N/A | AE15: N/A | AF15: N/A | AG15: N/A | AH15: Brown University | AI15: Providence, RI | AJ15: Ivy League | AK15: 3.9 | AL15: Applied Mathematics-Economics (BS) | AM15: 2027 | AN15: MLT, BLK Consulting | AO15: https://drive.google.com/open?id=10KVYEU3vbAxxWv0TMBH85d_6tQXNG0Ng | AP15: Private Equity, Asset Management, Management Consulting, Economic Consulting | AQ15: Bain, BCG, McKinsey, FTI Consulting | AR15: I am the most interested in consulting, either management or economic consulting. | AT15: Community Member
A16: 45753.941 | B16: Olatundun | C16: Badmus | D16: BLK - 24040 | E16: sxb1851@student.bham.ac.uk | F16: olatundun.badmus@yahoo.com | G16: Personal email | H16: =IF(G16="College/Secondary email:",E16,F16) -> olatundun.badmus@yahoo.com | I16: London | J16: Community Member | K16: +447380901007 | L16: Female | M16: Fall 2024 | N16: 2026 | O16: EMEA | P16: London (EMEA) | Q16: No | R16: Schroders | S16: London, UK | T16: Wealth Management | U16: 1 | V16: n/a | W16: Crowe | X16: London, UK | Y16: Accounting | Z16: 1 | AA16: n/a | AB16: n/a | AC16: n/a | AD16: n/a | AE16: n/a | AF16: n/a | AG16: n/a | AH16: University of Birmingham | AI16: Birmingham | AJ16: Russell Group | AK16: n/a | AL16: Economics | AM16: 2026 | AN16: SEO (EMEA), UpReach, Rare Recruitment | AO16: https://drive.google.com/open?id=17V0WdpCBdwelY-oyJoG7avPvWZnasMDQ | AP16: Investment Banking, Asset Management | AQ16: JP morgan | AT16: Education Pathways (IB, AWM, or PE)
A17: 45753.942 | B17: James | C17: Owusu-Ansah | D17: BLK-24045 | E17: jo444@cornell.edu | F17: jowuansah49@gmail.com | G17: College/Secondary email: | H17: =IF(G17="College/Secondary email:",E17,F17) -> jo444@cornell.edu | I17: Ithaca | J17: Community Member | K17: +16073272769 | L17: Male | M17: Fall 2024 | N17: 2027 | O17: North America | P17: New York City (U.S.) | Q17: Yes | R17: N/A | S17: N/A | T17: N/A | U17: N/A | V17: N/A | W17: Lafayette Square | X17: New York, New York | Y17: Private Credit | Z17: n/a | AA17: n/a | AB17: n/a | AC17: n/a | AD17: n/a | AE17: n/a | AF17: n/a | AG17: n/a | AH17: Cornell University | AI17: Ithaca | AJ17: Target | AK17: 3.5 | AL17: Information Science | AM17: 2027 | AN17: BLK | AO17: https://drive.google.com/open?id=1gleLrgWONtmCi6xKomYTsxA4y99K3af0 | AP17: Investment Banking, Sales and Trading, Private Equity, Asset Management, Venture Capital, Hedge Funds | AQ17: Ares Management | AT17: Analyst
A18: 45753.944 | B18: Ava | C18: Brown | D18: BLK - 24046 | E18: avabrown@stanford.edu | F18: aariellebrown@gmail.com | G18: Personal email | H18: =IF(G18="College/Secondary email:",E18,F18) -> aariellebrown@gmail.com | I18: Folsom, CA | J18: Community Member | K18: +19164910955 | L18: Female | M18: Fall 2024 | N18: 2026 | O18: North America | P18: N/A | Q18: Yes | R18: Milliman | S18: Chicago, IL | T18: actuarial | U18: 7-10 | V18: better compensation, better city, opportunity to work on a data science team | W18: Goldman Sachs | X18: New York City, NY | Y18: investment banking | Z18: 2 | AA18: wanted to work in investment banking, not insurance | AB18: Bridgewater Associates | AC18: New York City, NY | AD18: hedge fund | AE18: 2 | AF18: wanted to try something other than investment banking | AG18: NA | AH18: Stanford University | AI18: Stanford, CA | AJ18: Target | AK18: 4.1 | AL18: Data Science BS | AM18: 2026 | AN18: Girls Who Invest | AO18: https://drive.google.com/open?id=1WKm-vBi_KztdpCij9q61Tfiz4cSnw3a_ | AP18: Quantitative Finance (eg. Quant Trading), Management Consulting, Venture Capital, Hedge Funds, Technology | AQ18: Tech VC, roles blending business/CS/math/finance | AT18: Community Member
A19: 45753.947 | B19: Zorian | C19: Facey | D19: BLK-24144 | E19: Zorian_facey@brown.edu | F19: Zorianfacey@gmail.com | G19: Personal email | H19: =IF(G19="College/Secondary email:",E19,F19) -> Zorianfacey@gmail.com | I19: Oviedo, FL | J19: Analyst | K19: +13217465351 | L19: Female | M19: Fall 2024 | N19: 2027 | O19: North America | P19: N/A | Q19: Yes | R19: Leo Legacy (search fund) | S19: Remote | T19: Private equity analyst | U19: N/A | V19: N/A | W19: Wellington Management (incoming) | X19: Boston, MA | Y19: Asset management | Z19: I got matched through Girls Who Invest and was not permitted to apply elsewhere. | AA19: N/A | AB19: N/A | AC19: N/A | AD19: N/A | AE19: N/A | AF19: N/A | AG19: N/A | AH19: Brown University | AI19: Providence, RI | AJ19: Semi-target | AK19: 3.75 | AL19: Applied Mathematics & Economics | AM19: 2027 | AN19: MLT, Girls Who Invest | AO19: https://drive.google.com/open?id=1MWO7gqjlYq4Y2teYnEPNrc0iDJzyD2ti | AP19: Investment Banking, Private Equity, Asset Management, Equity Research | AQ19: Bain Capital, Carlyle, KKR, Fidelity, GS, MS | AR19: Very interested in PE, though I also am exploring investment management and research. | AT19: Analyst
A20: 45753.948 | B20: Obed | C20: Antwi-Baidoo | D20: 22250 | E20: oantwiba@nd.edu | F20: obedantwibaidoo@gmail.com | G20: Personal email | H20: =IF(G20="College/Secondary email:",E20,F20) -> obedantwibaidoo@gmail.com | I20: Ejisu-Krapa | J20: Executive board | K20: +12407080341 | L20: Male | M20: Spring 2022 | N20: 2025 | O20: North America | P20: N/A | Q20: Yes, but would need visa sponsorship after 3 years when my STEM OPT expires. | R20: University of Notre Dame | S20: Notre Dame, IN | T20: Wealth Management | U20: N/A | V20: N/A | W20: Bank of America | X20: New York, NY | Y20: Sales and trading | Z20: 2 | AA20: Wanted to explore | AB20: The Carlyle Group | AC20: New York, NY | AD20: Asset management | AE20: 5+ | AF20: Wanted a wider breadth of experience | AG20: N/A | AH20: University of Notre Dame | AI20: Notre Dame | AJ20: Target | AK20: 3.5 | AL20: Finance and Quantitative Economics | AM20: 2025 | AN20: SEO | AO20: https://drive.google.com/open?id=1ISb_VodWIGWqe4CZJ2oBkLi7fnoKSI_P | AP20: Investment Banking, Sales and Trading, Private Equity, Asset Management, Quantitative Finance (eg. Quant Trading), Management Consulting, Venture Capital, Hedge Funds, Business & Entreprenuership, Technology, Real Estate, Legal, Risk & Compliance, HR | AQ20: Any | AR20: I want to start from a point with the most optionality. | AT20: Alumni (only select if you are graduated/graduating this year)
A21: 45753.958 | B21: Paul | C21: Owusu-Ansah | D21: BLK - 24252 | E21: Rayvon.owusu-ansah@city.ac.uk | F21: paul.owusu-ansah@outlook.com | G21: Personal email | H21: =IF(G21="College/Secondary email:",E21,F21) -> paul.owusu-ansah@outlook.com | I21: London | J21: Analyst | K21: 07395543260 | L21: Male | M21: Fall 2024 | N21: 2026 | O21: EMEA | P21: London (EMEA) | Q21: No | R21: N/A | S21: N/A | T21: N/A | U21: N/A | V21: N/A | W21: Morgan Stanley | X21: London | Y21: Market Risk | Z21: Received full time offer | AA21: N/A | AB21: N/A | AC21: N/A | AD21: N/A | AE21: N/A | AF21: N/A | AG21: Received full time offer for MS didn’t accept because it was not my preferred business area. | AH21: City University of London | AI21: Londo | AJ21: Non-target | AK21: Expected 1st Class Honours | AL21: Mechanical Engineering | AM21: 2026 | AN21: SEO (EMEA) | AO21: https://drive.google.com/open?id=1rACKWwWt9yWzd14P3W2TjFPaGo90ni_- | AP21: Investment Banking, Private Equity | AQ21: N/A | AT21: Analyst
A22: 45753.961 | B22: Nihmatalai | C22: Olaojo | D22: BLK - 24188 | E22: n.olaojo@lse.ac.uk | F22: nihmatalai.olaojo8@gmail.com | G22: Personal email | H22: =IF(G22="College/Secondary email:",E22,F22) -> nihmatalai.olaojo8@gmail.com | I22: London | J22: Analyst | K22: +447955422844 | L22: Female | M22: Fall 2024 | N22: 2027 | O22: EMEA | P22: London (EMEA) | Q22: No | R22: N/A | S22: N/A | T22: N/A | U22: N/A | V22: N/A | W22: N/A | X22: N/A | Y22: N/A | Z22: N/A | AA22: N/A | AB22: N/A | AC22: N/A | AD22: N/A | AE22: N/A | AF22: N/A | AG22: N/A | AH22: London School of Economics and Political Science | AI22: London | AJ22: Target | AK22: N/A | AL22: Accounting and Finance | AM22: 2027 | AN22: SEO (EMEA), Rare Recruitment | AO22: https://drive.google.com/open?id=1OnqIhS613hbnxmlt64_QLYlrUWOfggHq | AP22: Investment Banking, Private Equity, Asset Management, Real Estate | AQ22: N/A | AT22: Analyst
A23: 45753.983 | B23: Xamora | C23: Reed | D23: BLK - 24194 | E23: xreed@aggies.ncat.edu | F23: reed.xamora@gmail.com | G23: Personal email | H23: =IF(G23="College/Secondary email:",E23,F23) -> reed.xamora@gmail.com | I23: Charlotte, NC | J23: Analyst | K23: +17048044258 | L23: Female | M23: Fall 2024 | N23: 2027 | O23: North America | P23: N/A | Q23: Yes | R23: Wells Fargo | S23: Charlotte, NC | T23: Corporate Finance | U23: 1 | V23: N/A | W23: N/A | X23: N/A | Y23: N/A | Z23: N/A | AA23: N/A | AB23: N/A | AC23: N/A | AD23: N/A | AE23: N/A | AF23: N/A | AG23: N/A | AH23: North Carolina A&T State University | AI23: Greensboro, NC | AJ23: HBCU (Historically Black Colleges and Universities) | AK23: 4 | AL23: Economics (Law) | AM23: 2027 | AN23: MLT, Forte, Greenwood Project | AO23: https://drive.google.com/open?id=1FbdVgS-aPP6RzHZx6vasc8lxS2jTXtx2 | AP23: Investment Banking, Sales and Trading, Private Equity, Asset Management, Venture Capital, Hedge Funds | AQ23: Alphine, Bain Capital, Evercore, Goldman Sachs, JP Morgan, KKR, Lazard, Morgan Stanley, Neuberger Berman, PWP, Roark, UBS, Warburg Pincus, Wells Fargo | AT23: Analyst
A24: 45753.994 | B24: Anelda | C24: Agyei | D24: BLK - 24056 | E24: aaagyei@gustavus.edu | F24: ladyanelda14@gmail.com | G24: Personal email | H24: =IF(G24="College/Secondary email:",E24,F24) -> ladyanelda14@gmail.com | I24: Houston | J24: Community Member | K24: +18325857515 | L24: Female | M24: Fall 2024 | N24: 2027 | O24: North America | P24: N/A | Q24: Require sponsorship in the future | R24: N/A | S24: N/A | T24: M/A | U24: N/A | V24: N/A | W24: NA | X24: N/A | Y24: N/A | Z24: N/A | AA24: N/A | AB24: N/A | AC24: N/A | AD24: N/A | AE24: N/A | AF24: N/A | AG24: N/A | AH24: Gustavus Adolphus College | AI24: St Peter | AJ24: Liberal Arts College, Non-Target School | AK24: 3.5 | AL24: Computer science | AM24: 2027 | AN24: Colorstack, rewriting the code | AO24: https://drive.google.com/open?id=1WF_7X5QlG_t0c9WCs9RXUTtO1WkOp6Wg | AP24: Asset Management, Technology | AQ24: Alphine | AT24: Community Member
A25: 45754.005 | B25: Chijioke | C25: Achebe | D25: BLK - 22249 | E25: coa13@georgetown.edu | F25: chijioke.achebe@gmail.com | G25: Personal email | H25: =IF(G25="College/Secondary email:",E25,F25) -> chijioke.achebe@gmail.com | I25: West Orange, NJ | J25: Analyst | K25: +19735184496 | L25: Male | M25: Fall 2022 | N25: 2025 | O25: North America | P25: N/A | Q25: Yes | R25: Essex County Prosecutor's Office | S25: West Orange, NJ | T25: Government | U25: N/A | V25: N/A | W25: UBA America | X25: New York, NY | Y25: Corporate Banking/Trade Finance | Z25: N/A | AA25: N/A | AB25: Morgan Stanley | AC25: New York, NY | AD25: Public Finance Investment Banking | AE25: 1 | AF25: N/A | AG25: N/A | AH25: Georgetown University | AI25: Washington, DC | AJ25: Target | AK25: 3.36 | AL25: International Politics | AM25: 2025 | AN25: N/A | AO25: https://drive.google.com/open?id=1vBAa5PcfoUUihYPMYN4PSi-xZ6Qq2YNR | AP25: Investment Banking, Sales and Trading, Private Equity, Asset Management, Management Consulting, Hedge Funds | AQ25: Morgan Stanley, Goldman Sachs, J.P. Morgan, Bank of America, Citi | AR25: I'm also very interested in commodity trading. Eventually, I want to invest in infrastructure projects across Africa - mining, railroads, energy, airports, ports, shipping, etc | AT25: Alumni (only select if you are graduated/graduating this year)
A26: 45754.094 | B26: Ezinne | C26: Okwesilieze | D26: BLK-24196 | E26: eo6856j@gre.ac.uk | F26: eokwesilieze1@gmail.com | G26: Personal email | H26: =IF(G26="College/Secondary email:",E26,F26) -> eokwesilieze1@gmail.com | I26: Essex | J26: Analyst | K26: +447908100192 | L26: Female | M26: Fall 2024 | N26: 2026 | O26: EMEA | P26: London (EMEA) | Q26: If I gain a work visa | R26: N/A | S26: N/A | T26: N/A | U26: N/A | V26: N/A | W26: Wellcome Trust | X26: Euston, London | Y26: Asset/Investment Management | Z26: I wasn’t of the right year yet to get an offer | AA26: N/A | AB26: N/A | AC26: N/A | AD26: N/A | AE26: N/A | AF26: N/A | AG26: N/A | AH26: Medway School of Pharmacy | AI26: Kent | AJ26: Non-target | AK26: 2:1 | AL26: Pharmacy | AM26: 2026 | AN26: SEO (EMEA), Rare Recruitment | AO26: https://drive.google.com/open?id=1rpc33kD4sQfekQWeOLZ2oaP8_AUetpmg | AP26: Private Equity, Asset Management, Venture Capital, Business & Entreprenuership | AQ26: Any reputable and inspiring firms | AR26: After doing an internship in asset management, investment management, and venture capital, I realized that my pharmacy background could be a great fit for these fields. I’m drawn to the idea of having a bigger impact by shaping industries like healthcare, tech, or pharmaceuticals on a larger scale, beyond just working directly with patients. The critical thinking and data analysis skills I’ve developed in pharmacy are highly transferable, and my knowledge of the healthcare industry can help identify investment opportunities in emerging technologies or drug developments. I’m also interested in the entrepreneurial side of these fields, where I could apply my expertise to fund or start innovative companies. Additionally, asset and investment management offer more career variety and growth, with the chance to work across different industries and expand my professional network. Lastly, the potential for higher compensation is an attractive incentive, especially as I look to build long-term financial security while tackling new challenges. Moving into these fields feels like a natural next step where I can leverage my skills, learn new ones, and make a bigger impact. | AT26: Education Pathways (IB, AWM, or PE)
A27: 45754.099 | B27: Jonathan | C27: Colon | D27: 24256 | E27: Jonathan.Colon58@bcmail.cuny.edu | F27: jonathanacolon2012@gmail.com | G27: Personal email | H27: =IF(G27="College/Secondary email:",E27,F27) -> jonathanacolon2012@gmail.com | I27: New York, NY | J27: Analyst | K27: 9293619519 | L27: Male | M27: Fall 2024 | N27: 2027 | O27: North America | P27: New York City (U.S.) | Q27: Yes | R27: Soundboard Venturefund | S27: New York, NY | T27: Venture Capital | U27: N/A | V27: N/A | W27: Brown Advisory | X27: New York, NY | Y27: Buyside, Wealth Management | Z27: 1 | AA27: N/A | AB27: MD Sass Investment Services | AC27: New York, NY | AD27: Equity Research | AE27: N/A | AF27: N/A | AG27: Morgan Stanley | AH27: Brooklyn College | AI27: CUNY Brooklyn College | AJ27: Non-target | AK27: 4 | AL27: Economic Analysis | AM27: 2027 | AN27: SEO, Project Destined, ALPFA, Wall Street Bound, Hello HIVE, Student Government | AO27: https://drive.google.com/open?id=1v6m_bFc2VA4CUqqLEAuuSJvSw3uVdkd3 | AP27: Investment Banking, Private Equity, Venture Capital, Real Estate | AQ27: Black Rock, Blackstone, Goldman Sachs, Bridgewater, UBS, DWS, CBRE, Blue Owl Capital, Warburg Pincus | AR27: I am very interested in breaking into IB, and heading down a career path that lands me at a Private Equity Fund, or in a role involving Capital Markets within Real Estate Investment Banking | AT27: Analyst
A28: 45754.148 | B28: Charbel | C28: Adjogble | D28: BLK - 24011 | E28: cadjogble@bowdoin.edu | F28: charbelelomadjogble@gmail.com | G28: Personal email | H28: =IF(G28="College/Secondary email:",E28,F28) -> charbelelomadjogble@gmail.com | I28: Newark | J28: Community Member | K28: 9737155324 | L28: Male | M28: Spring 2024 | N28: 2026 | O28: North America | P28: New York City (U.S.) | Q28: Yes | R28: N/A | S28: N/A | T28: N/A | U28: N/A | V28: N/A | W28: N/A | X28: N/A | Y28: N/A | Z28: N/A | AA28: N/A | AB28: Bank of America | AC28: Dallas, Texas | AD28: Global Operations Development | AE28: 1 | AF28: N/A | AG28: N/A | AH28: Bowdoin College | AI28: Brunswick, Maine | AJ28: Liberal Arts College, Non-Target School | AK28: 3.1 | AL28: Economics | AM28: 2026 | AN28: SEO | AO28: https://drive.google.com/open?id=1WAhefabIEtjXWtfxzIVLU2Z3-q4owKus | AP28: Private Equity, Asset Management, Management Consulting, Business & Entreprenuership, Technology | AQ28: JPMorgan Chase, Deutsche Bank | AT28: Community Member
A29: 45754.202 | B29: David | C29: Ariyo | D29: BLK-24246 | E29: Ucnvd08@ucl.ac.uk | F29: DavidArriyo15@gmail.com | G29: Personal email | H29: =IF(G29="College/Secondary email:",E29,F29) -> DavidArriyo15@gmail.com | I29: London | J29: Analyst | K29: +447930300316 | L29: Male | M29: Fall 2024 | N29: 2025 | O29: EMEA | P29: London (EMEA) | Q29: No | R29: N/A | S29: N/A | T29: N/A | U29: N/A | V29: N/A | W29: N/A | X29: N/A | Y29: N/A | Z29: N/A | AA29: N/A | AB29: Standard Chartered | AC29: London | AD29: Client coverage | AE29: 1 | AF29: N/A | AG29: Standard Chartered | AH29: University College London | AI29: London | AJ29: Russed group | AK29: 2:1 | AL29: Pharmacy | AM29: 2025 | AN29: N/A | AO29: https://drive.google.com/open?id=10ngrzdNG30QZicjH9i2arBJa3DmSo_wM | AP29: Asset Management, Wealth management, Credit risk | AQ29: JP morgan, Goldman Sachs | AT29: Alumni (only select if you are graduated/graduating this year)
A30: 45754.23 | B30: Ausar | C30: Myers | D30: 24089 | E30: Ausarmyers@sandiego.edu | F30: Am23.myers@gmail.com | G30: College/Secondary email: | H30: =IF(G30="College/Secondary email:",E30,F30) -> Ausarmyers@sandiego.edu | I30: Miami, Florida | J30: Analyst | K30: 17866605695 | L30: Male | M30: Fall 2024 | N30: 2027 | O30: North America | P30: N/A | Q30: Yes | R30: The Shark Group | S30: Miami, Florida | T30: Private Equity | U30: 1 | V30: N/A | W30: Project Destined | X30: New York, New York | Y30: Provate Equity | Z30: 1 | AA30: N/A | AB30: Nomura | AC30: New York, New York | AD30: Global Markets | AE30: 1 | AF30: N/A | AG30: N/A | AH30: The University of San Diego | AI30: San Diego | AJ30: Non-target | AK30: 3.7 | AL30: International Business | AM30: 2027 | AN30: MLT, Project Destined, HeadStart | AO30: https://drive.google.com/open?id=1GB2pvqbWT4-z8lbu0-KVcJahLlKrgp4P | AP30: Private Equity, Venture Capital, Business & Entreprenuership | AQ30: LLR, Roark, Advent, Bain Capital, Carlyle, and Alpine | AR30: I have currently found my Junior summer internship but as I align more with private equity, I am preparing for my graduating summer. | AT30: Analyst
A31: 45754.239 | B31: Odelia | C31: Uwanogho | D31: BLK - 24062 | E31: odelia.uwanogho1@gmail.com | F31: odelia.uwanogho1@gmail.com | G31: Personal email | H31: =IF(G31="College/Secondary email:",E31,F31) -> odelia.uwanogho1@gmail.com | I31: Bristol | J31: Community Member | K31: +447309681988 | L31: Female | M31: Fall 2024 | N31: 2028 | O31: EMEA | P31: N/A | Q31: No | R31: N/A | S31: N/A | T31: N/A | U31: N/A | V31: N/A | W31: N/A | X31: N/A | Y31: N/A | Z31: N/A | AA31: N/A | AB31: N/A | AC31: N/A | AD31: N/A | AE31: N/A | AF31: N/A | AG31: N/A | AH31: University of Bristol | AI31: Bristol | AJ31: Target | AK31: N/A | AL31: Business and management with innovation | AM31: 2028 | AN31: n/a | AO31: https://drive.google.com/open?id=1WA-a3a2Hel79BTArfeKJeMMGslea8Iok | AP31: Investment Banking, Private Equity, Asset Management, Management Consulting, Business & Entreprenuership | AQ31: N/A | AT31: Education Pathways (IB, AWM, or PE)
A32: 45754.259 | B32: Leon | C32: Ross | D32: 23276 | E32: va22924@bristol.ac.uk | F32: leon2ross9@gmail.com | G32: Personal email | H32: =IF(G32="College/Secondary email:",E32,F32) -> leon2ross9@gmail.com | I32: Bristol | J32: Executive board | K32: 447398562010 | L32: Male | M32: Fall 2023 | N32: 2025 | O32: EMEA | P32: N/A | Q32: No | R32: Lloyds Banking Group | S32: London | T32: Commercial Banking | U32: 1 | V32: n/a | W32: J.P. Morgan | X32: London | Y32: Investment Banking | Z32: 1 | AA32: n/a | AB32: n/a | AC32: n/a | AD32: n/a | AE32: n/a | AF32: n/a | AG32: J.P. Morgan | AH32: University of Bristol | AI32: Bristol | AJ32: Target | AK32: 1st | AL32: Mathematics | AM32: 2025 | AN32: SEO (EMEA), UpReach, Rare Recruitment | AO32: https://drive.google.com/open?id=1luHQ_wUzQNC-2WXeESQqkxrrq6zD2T7H | AP32: Investment Banking, Private Equity | AQ32: All private equity firms | AR32: Interested in Private Equity opportunities in the UK and US | AT32: Alumni (only select if you are graduated/graduating this year)
A33: 45754.282 | B33: Justin | C33: Holmes | D33: BLK-23056 | E33: Justin.holmes@bc.edu | F33: Justindavidholmes@gmail.com | G33: College/Secondary email: | H33: =IF(G33="College/Secondary email:",E33,F33) -> Justin.holmes@bc.edu | I33: Westport, CT | J33: Community Member | K33: +12039706135 | L33: Male | M33: Spring 2023 | N33: 2026 | O33: North America | P33: Boston (U.S.) | Q33: Yes | R33: Artemis Real Estate Partners | S33: Washington, D.C. | T33: RE Private Equity | U33: N/a | V33: N/A` | W33: Revelstoke Capital Partners | X33: Denver, Colorado | Y33: Private Equity | Z33: 2 | AA33: Decided not to do consulting, was more interested in PE. Also another firm was in NYC and I wanted a change of scenery. | AB33: Moelis & Co. | AC33: New York, New York | AD33: Investment Banking | AE33: 5 | AF33: Moelis & Co. was top choice for my self. | AG33: N/A | AH33: Boston College | AI33: Boston, MA | AJ33: Target | AK33: 3.75 | AL33: Finance | AM33: 2026 | AN33: MLT, SEO | AO33: https://drive.google.com/open?id=1OHxZ5DOIMQMSqsFJ-N6WgncBxisKLZld | AP33: Investment Banking, Private Equity, Hedge Funds, Real Estate | AQ33: Arsenal Capital Partners, Bain Capital, Carlyle, KKR, Roark Capital Partners, Warburg Pincus | AR33: Upcoming internship is generalist program, I am still undecided on where I want to go but want to try all the different groups to see what I am most interested in. Currently I am most interested in TMT, RE, and Healthcare/Consumer Retail. | AT33: Community Member
A34: 45754.297 | B34: George | C34: Orji | D34: BLK-24095 | E34: george.orji@warwick.ac.uk | F34: georgeorji05@gmail.com | G34: Personal email | H34: =IF(G34="College/Secondary email:",E34,F34) -> georgeorji05@gmail.com | I34: London | J34: Community Member | K34: +447947693396 | L34: Male | M34: Fall 2024 | N34: 2026 | O34: EMEA | P34: N/A | Q34: No | R34: AKO Capital | S34: London, United Kingdom | T34: Asset Management | U34: 2 | V34: Internship was not long enough - would only be for 1 week | W34: Baird | X34: London, United Kingdom | Y34: Investment Banking | Z34: 1 | AA34: N/A | AB34: N/A | AC34: N/A | AD34: N/A | AE34: N/A | AF34: N/A | AG34: N/A | AH34: The University of Warwick | AI34: Coventry | AJ34: Target | AK34: 0.71 | AL34: Economics - Politics Minor | AM34: 2026 | AN34: SEO (EMEA), Rare Recruitment | AO34: https://drive.google.com/open?id=1rVsOCqIWQZhBvMfIr5YAFGJMzeMVTBGW | AP34: Investment Banking | AQ34: Citi, UBS, Barclays | AR34: Aim is to spend 2-4 years in investment banking before pivoting to the buy-side, with a particular interest in Private Equity | AT34: Community Member
A35: 45754.316 | B35: Otman | C35: Atfi | D35: BLK-24005 | E35: otmanatfi@vt.edu | F35: otmanatfi04@gmail.com | G35: Personal email | H35: =IF(G35="College/Secondary email:",E35,F35) -> otmanatfi04@gmail.com | I35: Richmond, VA | J35: Analyst | K35: +16176787176 | L35: Male | M35: Spring 2024 | N35: 2026 | O35: North America | P35: N/A | Q35: Yes | R35: N/A | S35: N/A | T35: N/A | U35: N/A | V35: N/A | W35: Dominion Energy | X35: Richmond, VA | Y35: Energy | Z35: 1 | AA35: N/A | AB35: Wells Fargo | AC35: Boston, MA | AD35: Banking | AE35: 3 | AF35: I believed that this opportunity closely aligns with my future goals. | AG35: N/A | AH35: Virginia Tech | AI35: Blacksburg | AJ35: Non-target | AK35: 3.63 | AL35: Entrepreneurship Innovation Technology and Business Management | AM35: 2026 | AN35: SEO | AO35: https://drive.google.com/open?id=1H9Yxs0NaibyPCNQOwnx1lGDikSIGWFmd | AP35: Asset Management, Management Consulting, Business & Entreprenuership | AQ35: Goldman Sachs, J.P. Morgan, Morgan Stanley, UBS | AT35: Community Member
A36: 45754.319 | B36: James | C36: Benjamin | D36: BLK - 23397 | E36: j.benjamin3@lse.ac.uk | F36: jm.benjamin@outlook.com | G36: Personal email | H36: =IF(G36="College/Secondary email:",E36,F36) -> jm.benjamin@outlook.com | I36: London | J36: Executive board | K36: +447478243983 | L36: Male | M36: Spring 2024 | N36: 2025 | O36: EMEA | P36: London (EMEA) | Q36: No | R36: HSBC, PwC | S36: London, UK | T36: Asset Management | U36: 2 | V36: N/A | W36: PwC | X36: London | Y36: Investment Banking | Z36: 1 | AA36: N/A | AB36: Barings Investment Management | AC36: London | AD36: Asset Management | AE36: 2 | AF36: Pay package | AG36: Morgan Stanley (off-cycle internship) | AH36: The London School of Economics and Political Science | AI36: London | AJ36: Target | AK36: 3.7 | AL36: MSc Accounting and Finance | AM36: 2025 | AN36: SEO (EMEA), Rare Recruitment | AO36: https://drive.google.com/open?id=1KIavo1mW6_AQnsL9bVVi9Um_E8Wy77oK | AP36: Investment Banking, Private Equity, Asset Management, Hedge Funds | AQ36: All Partners | AR36: Looking to move into private credit or private equity long-term | AT36: Alumni (only select if you are graduated/graduating this year)
A37: 45754.354 | B37: Isaiah | C37: Joyner | D37: 24244 | E37: ijjoyner@unc.edu | F37: i.joyner023@gmail.com | G37: Personal email | H37: =IF(G37="College/Secondary email:",E37,F37) -> i.joyner023@gmail.com | I37: Asheville | J37: Analyst | K37: 8284421521 | L37: Male | M37: Fall 2024 | N37: 2027 | O37: North America | P37: N/A | Q37: Yes | R37: International Investments LLC | S37: Raleigh, NC | T37: Investment Management | U37: N/A | V37: N/A | W37: Unc Management Company | X37: Chapel Hill, NC | Y37: Endowment Management | Z37: 2 | AA37: N/A | AB37: N/A | AC37: N/A | AD37: N/A | AE37: N/A | AF37: N/A | AG37: N/A | AH37: University of North Carolina at Chapel Hill | AI37: Chapel Hill | AJ37: Non-target | AK37: 3.63 | AL37: Business Admin(Finance) | AM37: 2027 | AN37: MLT, SEO | AO37: https://drive.google.com/open?id=1cc79unHY2I3HtGKSyqYgAcrb4LjPGcbn | AP37: Investment Banking, Private Equity, Asset Management, Venture Capital, Hedge Funds | AQ37: BB Investment Banks, Asset managers, Hedge Funds | AR37: I’m interested in banking or fundamental type investing jobs. | AT37: Analyst
A38: 45754.368 | B38: Che | C38: Bernard | D38: 23322 | E38: che.bernard@st-hughs.ox.ac.uk | F38: chelarsbernard@gmail.com | G38: Personal email | H38: =IF(G38="College/Secondary email:",E38,F38) -> chelarsbernard@gmail.com | I38: London | J38: Community Member | K38: +447306527785 | L38: Male | M38: Spring 2023 | N38: 2027 | O38: EMEA | P38: London (EMEA) | Q38: No | R38: Allenby Capital | S38: London | T38: Investment Banking | U38: 1 | V38: N/A | W38: Millenium Management | X38: London | Y38: Hedge Fund | Z38: 1 | AA38: N/A | AB38: N/A | AC38: N/A | AD38: N/A | AE38: N/A | AF38: N/A | AG38: N/A | AH38: University of Oxford | AI38: Oxford | AJ38: Target | AK38: 2:1 | AL38: Chemistry | AM38: 2027 | AN38: SEO (EMEA), UpReach, Rare Recruitment | AO38: https://drive.google.com/open?id=1AyGTWUHp1KyUV2kK6soptECDt8SPTkcK | AP38: Investment Banking, Private Equity, Hedge Funds | AQ38: Citadel, Blackstone | AT38: Community Member
A39: 45754.397 | B39: Jaden | C39: Mighten | D39: BLK - 23038 | E39: jdmighten@gmail.com | F39: mightenjaden@gmail.com | G39: Personal email | H39: =IF(G39="College/Secondary email:",E39,F39) -> mightenjaden@gmail.com | I39: Nottingham | J39: Portfolio Manager | K39: +447546287551 | L39: Male | M39: Spring 2023 | N39: 2026 | O39: EMEA | P39: London (EMEA) | Q39: No | R39: Scotiabank | S39: London | T39: Investment Banking | U39: 23 Spring week offers, 8 summer internship offers | V39: NA | W39: Goldman Sachs | X39: London | Y39: Investment Banking | Z39: NA | AA39: NA | AB39: NA | AC39: NA | AD39: NA | AE39: NA | AF39: NA | AG39: NA | AH39: LSE | AI39: London | AJ39: Target | AK39: 4 | AL39: Economics | AM39: 2026 | AN39: SEO (EMEA), UpReach, Rare Recruitment | AO39: https://drive.google.com/open?id=1l8zmVYfBkZu0lYCnwIFsH4oejyObf2uT | AP39: Investment Banking, Private Equity, Asset Management, Quantitative Finance (eg. Quant Trading), Hedge Funds, Business & Entreprenuership | AQ39: Private Equity Firms, Hedge Funds | AR39: 2 + 2, IB to HF/PE | AT39: Analyst
A40: 45754.409 | B40: Jeffrey | C40: Odiase | D40: 23119 | E40: odiase@bu.edu | F40: jeoj.ntw@gmail.com | G40: College/Secondary email: | H40: =IF(G40="College/Secondary email:",E40,F40) -> odiase@bu.edu | I40: Newark, New Jersey | J40: Community Member | K40: 9735190398 | L40: Male | M40: Spring 2024 | N40: 2027 | O40: North America | P40: Boston (U.S.) | Q40: Yes | R40: BlackRock | S40: Manhattan, NY | T40: Asset Management | U40: N/A | V40: N/A | W40: BlackRock | X40: Manhattan, NY | Y40: Asset Management | Z40: N/A | AA40: N/A | AB40: N/A | AC40: N/A | AD40: N/A | AE40: N/A | AF40: N/A | AG40: N/A | AH40: Boston University | AI40: Boston, MA | AJ40: Non-target | AK40: 3.03 | AL40: Economics and Computer Science | AM40: 2027 | AN40: N/A | AO40: https://drive.google.com/open?id=162jGPQdvCw12F78RltRi2JIWogkAO5Qu | AP40: Sales and Trading, Private Equity, Asset Management, Quantitative Finance (eg. Quant Trading), Venture Capital, Hedge Funds, Business & Entreprenuership, Technology, Real Estate | AQ40: Jane Street, Fidelity, JPMorgan | AT40: Education Pathways (IB, AWM, or PE)
...

Sheet Mail merge sheet
A1: name | C1: Blk id | G1: Preffered Email | O1: City | AT1: Filter Rows to Merge
A2: Brian | B2: Davids | C2: 23388 | D2: davidsbg@bc.edu | E2: bzachdavids@gmail.com | F2: College/Secondary email: | G2: =IF(F2="College/Secondary email:",D2,E2) -> davidsbg@bc.edu | H2: Glenn Dale | I2: Analyst | J2: +13015182003 | K2: Male | L2: Spring 2024 | M2: 2027 | N2: North America | O2: Boston (U.S.) | P2: Yes | Q2: Long Horizon Partners | R2: Virtual | S2: Private Equity | T2: 1 | U2: N/A | V2: PWC | W2: New York, NY | X2: Consulting | Y2: 1 | Z2: N/A | AA2: Evercore | AB2: New York, NY | AC2: Investment Banking | AD2: 1 | AE2: N/A | AF2: N/A | AG2: Boston College | AH2: Newton, MA | AI2: Target | AJ2: 3.7 | AK2: Finance and Business Analytics | AL2: 2027 | AM2: MLT, SEO | AN2: https://drive.google.com/open?id=1XWClHCwCx5aNJniGdFhaFayO5decO7qu | AO2: Investment Banking, Private Equity, Venture Capital, Hedge Funds | AP2: Advent, DE Shaw, Warburg | AQ2: Pursuing Banking but interested in Public and Private Markets Investing for After Analyst Years | AS2: Analyst | AT2: Merged on Nov 07, 2025 18:05:00
A3: EJ | B3: Ibhawoh | C3: 23043 | D3: ibhawoha@mcmaster.ca | E3: ejiyeibhawoh@gmail.com | F3: College/Secondary email: | G3: =IF(F3="College/Secondary email:",D3,E3) -> ibhawoha@mcmaster.ca | H3: Hamilton | I3: Analyst | J3: 19057450150 | K3: Male | L3: Fall 2022 | M3: 2026 | N3: North America | O3: Toronto (Canada) | P3: Yes | Q3: BDC | R3: Toronto | S3: Venture Capital | T3: N/A | U3: N/A | V3: CIBC | W3: Toronto | X3: Sales & Trading | Y3: N/A | Z3: N/A | AA3: RBC | AB3: Toronto | AC3: Investment Banking | AD3: N/A | AE3: N/A | AF3: N/A | AG3: McMaster University | AH3: Hamilton | AI3: Non-target | AJ3: 4 | AK3: Commerce | AL3: 2026 | AM3: Bridging the Gap | AN3: https://drive.google.com/open?id=1iSck4HjUOK-tMmh3tgnAAAmBNI8Eytqq | AO3: Investment Banking, Private Equity, Asset Management | AP3: JP Morgan, Goldman Sachs, Morgan Stanley | AQ3: Any American Investment Banking Position | AS3: Analyst | AT3: Merged on Nov 07, 2025 18:05:01
A4: Keyonte’ | B4: Doughty | C4: BLK - 23311 | D4: keyonte.d.doughty@vanderbilt.edu | E4: kd.doughty66@gmail.com | F4: Personal email | G4: =IF(F4="College/Secondary email:",D4,E4) -> kd.doughty66@gmail.com | H4: Tuscaloosa, AL | I4: Senior analyst | J4: 2058726413 | K4: Male | L4: Spring 2024 | M4: 2025 | N4: North America | O4: N/A | P4: Yes | Q4: Congressional Black Caucus Foundation | R4: Washington, D.C. | S4: Government | T4: N/A | U4: N/A | V4: Affiliated Managers Group | W4: Boston, MA | X4: Asset Management | Y4: N/A | Z4: N/A | AA4: Citigroup | AB4: New York, New York | AC4: Sales & Trading | AD4: 1 | AE4: N/A | AF4: Citi | AG4: Vanderbilt University | AH4: Nashville, TN | AI4: Target | AJ4: 3.63 | AK4: Human & Organizational Development, Political Science | AL4: 2025 | AM4: SEO | AN4: https://drive.google.com/open?id=1AWIuUcQF6mEJKQCCW_AbEXIbW1fEi7WZ | AO4: Investment Banking, Sales and Trading, Private Equity, Real Estate, Legal, Risk & Compliance | AP4: Bain & Capital, Carlyle Group, J.P. Morgan, Goldman Sachs, TD Cowen | AQ4: Interested in going to PE post S&T | AS4: Alumni (only select if you are graduated/graduating this year) | AT4: Merged on Nov 07, 2025 18:05:04
A5: Malik | B5: Denney | C5: BLK-23146 | D5: Malik.Denney@bison.Howard.edu | E5: Malik.denney1@gmail.con | F5: Personal email | G5: =IF(F5="College/Secondary email:",D5,E5) -> Malik.denney1@gmail.con | H5: Atlanta | I5: Analyst | J5: 4046838903 | K5: Male | L5: Spring 2023 | M5: 2026 | N5: North America | O5: N/A | P5: Yes | Q5: Deloittw | R5: Atlanta, GA | S5: Consulting | T5: 2 | U5: Higher pay | V5: Permira Advisors | W5: New York, New York | X5: Private equity | Y5: 3 | Z5: Prestige | AA5: BMO Capital Markets | AB5: New York, NY | AC5: Investment Banking | AD5: 1 | AE5: Na | AF5: Na | AG5: Howard University | AH5: Washington D.C | AI5: Non-target | AJ5: 3.3 | AK5: Finance | AL5: 2026 | AM5: Huig | AN5: https://drive.google.com/open?id=1lMpAUbh_PZNJoJMd4p5HEoGGoWu_6ITj | AO5: Investment Banking | AP5: Evercore | AS5: Education Pathways (IB, AWM, or PE) | AT5: Merged on Nov 07, 2025 18:05:05
A6: Patrick | B6: Bongo | C6: 24020 | D6: patrick.m.bongo.27@dartmouth.edu | E6: MVOO21032GMAIL.COM | F6: College/Secondary email: | G6: =IF(F6="College/Secondary email:",D6,E6) -> patrick.m.bongo.27@dartmouth.edu | H6: Mombasa | I6: Analyst | J6: +6032668130 | K6: Male | L6: Spring 2024 | M6: 2027 | N6: North America | O6: N/A | P6: Yes | Q6: N/A | R6: N/A | S6: N/A | T6: N/A | U6: N/A | V6: N/A | W6: N/A | X6: N/A | Y6: N/A | Z6: N/A | AA6: Nomura | AB6: NYC | AC6: Sales & Trading | AD6: 2 | AE6: Preference | AF6: N/A | AG6: Dartmouth College | AH6: Hanover | AI6: Target | AJ6: 3.74 | AK6: Comp Science | AL6: 2027 | AM6: Black Gen Finance | AN6: https://drive.google.com/open?id=16Pz6ikkt1Lbyfoxv_PL_tlhdmij0Vh2w | AO6: Investment Banking, Sales and Trading, Private Equity | AP6: PE | AQ6: PE and any other PE organizations | AS6: Analyst | AT6: Merged on Nov 07, 2025 18:05:05
A7: Maya | B7: Lewis | C7: BLK-24102 | D7: mayajlewis@uchicago.edu | E7: tobidairo@outlook.com | F7: College/Secondary email: | G7: =IF(F7="College/Secondary email:",D7,E7) -> mayajlewis@uchicago.edu | H7: Burlington, NJ | I7: Analyst | J7: 9083009622 | K7: Female | L7: Fall 2024 | M7: 2028 | N7: North America | O7: N/A | P7: Yes | Q7: N/A | R7: N/A | S7: N/A | T7: N/A | U7: N/A | V7: N/A | W7: N/A | X7: N/A | Y7: N/A | Z7: N/A | AA7: N/A | AB7: N/A | AC7: N/A | AD7: N/A | AE7: N/A | AF7: N/A | AG7: University of Chicago | AH7: Chicago | AI7: Target | AJ7: 3.3 | AK7: Business Economics & Public Policy | AL7: 2028 | AM7: INROADS, Girls Who Invest, Project Destined | AN7: https://drive.google.com/open?id=1RiHQVITmVo-4QtHRbp2hoX6czBXfkctD | AO7: Sales and Trading, Venture Capital, Hedge Funds, Economic Consulting, Equity Research | AP7: Nera, US Bank, Cornerstone Research | AS7: Analyst | AT7: Merged on Nov 07, 2025 18:05:06
A8: Jamari | B8: Myers | C8: BLK - 23372 | D8: jamari_myers@brown.edu | E8: jamari.myers2023@gmail.com | F8: College/Secondary email: | G8: =IF(F8="College/Secondary email:",D8,E8) -> jamari_myers@brown.edu | H8: Mansfield, TX | I8: Analyst | J8: +19789980846 | K8: Male | L8: Spring 2024 | M8: 2027 | N8: North America | O8: N/A | P8: Yes | Q8: Decatur Street Capital | R8: Remote | S8: Private Equity - Search Fund | T8: 3 | U8: This internship was the best fit for what I hoped to gain. | V8: J.P. Morgan | W8: New York, New York | X8: Investment Banking | Y8: 1 | Z8: N/A | AA8: N/A, J.P. Morgan | AB8: New York, New York | AC8: Investment Banking | AD8: N/A | AE8: N/A | AF8: N/A | AG8: Brown University | AH8: Providence, RI | AI8: Target | AJ8: 3.75 | AK8: Business Economics and Entrepreneurship | AL8: 2027 | AM8: SEO | AN8: https://drive.google.com/open?id=1cvj_Ut2UurUuoFcS8Zx3chzUe28w8nzo | AO8: Investment Banking, Private Equity, Business & Entreprenuership | AP8: Apollo | AS8: Analyst | AT8: Merged on Nov 07, 2025 18:05:07
A9: Christela | B9: Bosco | C9: BLK - 23351 | D9: Christelabosco@gmail.com | E9: Christelabosco@gmail.com | F9: Personal email | G9: =IF(F9="College/Secondary email:",D9,E9) -> Christelabosco@gmail.com | H9: Nashville, TN | I9: Roark fellow | J9: 1 | K9: Female | L9: Spring 2024 | M9: 2027 | N9: North America | O9: Atlanta (U.S.) | P9: Yes | Q9: N/A | R9: N/A | S9: N/A | T9: N/A | U9: N/A | V9: N/A | W9: N/A | X9: N/A | Y9: N/A | Z9: N/A | AA9: N/A | AB9: N/A | AC9: N/A | AD9: N/A | AE9: N/A | AF9: N/A | AG9: University of Tennessee | AH9: Knoxville | AI9: Non-target | AJ9: 4 | AK9: Business | AL9: 2027 | AM9: SEO, Girls Who Invest | AN9: https://drive.google.com/open?id=130pSyXHdOXzXoDZg7PCHxTxFFC30zM46 | AO9: Private Equity, Management Consulting, Real Estate, Legal, Risk & Compliance | AP9: Blackstone, Ares, Carlyle, KKR | AS9: Community Member | AT9: Merged on Nov 07, 2025 18:05:08
A10: Steve | B10: Fotso | C10: BLK - 24074 | D10: fotsos@mcmaster.ca | E10: fotsoryan@gmail.com | F10: Personal email | G10: =IF(F10="College/Secondary email:",D10,E10) -> fotsoryan@gmail.com | H10: Hamilton, Canada | I10: Senior analyst | J10: 12265064621 | K10: Male | L10: Fall 2024 | M10: 2026 | N10: North America | O10: Toronto (Canada) | P10: No | Q10: Investment Management Corporation of Ontario (IMCO) | R10: Toronto, Ontario | S10: Asset Managament | T10: N/A | U10: N/A | V10: Toronto Dominion (TD) Bank | W10: Toronto, Ontario | X10: Compliance | Y10: N/A | Z10: N/A | AA10: N/A | AB10: N/A | AC10: N/A | AD10: N/A | AE10: N/A | AF10: N/A | AG10: McMaster University | AH10: Hamilton, Canada | AI10: Non-target | AJ10: 3.7 | AK10: Finance | AL10: 2026 | AM10: BLK, Investa | AN10: https://drive.google.com/open?id=12TOa85ti3NI1BDLBYA6chnLLNueEtTGS | AO10: Investment Banking, Sales and Trading, Asset Management | AP10: TD Securities | AS10: Education Pathways (IB, AWM, or PE) | AT10: Merged on Nov 07, 2025 18:05:09
A11: Zorian | B11: Facey | C11: BLK-24144 | D11: Zorian_facey@brown.edu | E11: Zorianfacey@gmail.com | F11: Personal email | G11: =IF(F11="College/Secondary email:",D11,E11) -> Zorianfacey@gmail.com | H11: Oviedo, FL | I11: Analyst | J11: +13217465351 | K11: Female | L11: Fall 2024 | M11: 2027 | N11: North America | O11: N/A | P11: Yes | Q11: Leo Legacy (search fund) | R11: Remote | S11: Private equity analyst | T11: N/A | U11: N/A | V11: Wellington Management (incoming) | W11: Boston, MA | X11: Asset management | Y11: I got matched through Girls Who Invest and was not permitted to apply elsewhere. | Z11: N/A | AA11: N/A | AB11: N/A | AC11: N/A | AD11: N/A | AE11: N/A | AF11: N/A | AG11: Brown University | AH11: Providence, RI | AI11: Semi-target | AJ11: 3.75 | AK11: Applied Mathematics & Economics | AL11: 2027 | AM11: MLT, Girls Who Invest | AN11: https://drive.google.com/open?id=1MWO7gqjlYq4Y2teYnEPNrc0iDJzyD2ti | AO11: Investment Banking, Private Equity, Asset Management, Equity Research | AP11: Bain Capital, Carlyle, KKR, Fidelity, GS, MS | AQ11: Very interested in PE, though I also am exploring investment management and research. | AS11: Analyst | AT11: Merged on Nov 07, 2025 18:05:10
A12: Paul | B12: Owusu-Ansah | C12: BLK - 24252 | D12: Rayvon.owusu-ansah@city.ac.uk | E12: paul.owusu-ansah@outlook.com | F12: Personal email | G12: =IF(F12="College/Secondary email:",D12,E12) -> paul.owusu-ansah@outlook.com | H12: London | I12: Analyst | J12: 07395543260 | K12: Male | L12: Fall 2024 | M12: 2026 | N12: EMEA | O12: London (EMEA) | P12: No | Q12: N/A | R12: N/A | S12: N/A | T12: N/A | U12: N/A | V12: Morgan Stanley | W12: London | X12: Market Risk | Y12: Received full time offer | Z12: N/A | AA12: N/A | AB12: N/A | AC12: N/A | AD12: N/A | AE12: N/A | AF12: Received full time offer for MS didn’t accept because it was not my preferred business area. | AG12: City University of London | AH12: Londo | AI12: Non-target | AJ12: Expected 1st Class Honours | AK12: Mechanical Engineering | AL12: 2026 | AM12: SEO (EMEA) | AN12: https://drive.google.com/open?id=1rACKWwWt9yWzd14P3W2TjFPaGo90ni_- | AO12: Investment Banking, Private Equity | AP12: N/A | AS12: Analyst | AT12: Merged on Nov 07, 2025 18:05:14
A13: Nihmatalai | B13: Olaojo | C13: BLK - 24188 | D13: n.olaojo@lse.ac.uk | E13: nihmatalai.olaojo8@gmail.com | F13: Personal email | G13: =IF(F13="College/Secondary email:",D13,E13) -> nihmatalai.olaojo8@gmail.com | H13: London | I13: Analyst | J13: +447955422844 | K13: Female | L13: Fall 2024 | M13: 2027 | N13: EMEA | O13: London (EMEA) | P13: No | Q13: N/A | R13: N/A | S13: N/A | T13: N/A | U13: N/A | V13: N/A | W13: N/A | X13: N/A | Y13: N/A | Z13: N/A | AA13: N/A | AB13: N/A | AC13: N/A | AD13: N/A | AE13: N/A | AF13: N/A | AG13: London School of Economics and Political Science | AH13: London | AI13: Target | AJ13: N/A | AK13: Accounting and Finance | AL13: 2027 | AM13: SEO (EMEA), Rare Recruitment | AN13: https://drive.google.com/open?id=1OnqIhS613hbnxmlt64_QLYlrUWOfggHq | AO13: Investment Banking, Private Equity, Asset Management, Real Estate | AP13: N/A | AS13: Analyst | AT13: Merged on Nov 07, 2025 18:05:15
A14: Xamora | B14: Reed | C14: BLK - 24194 | D14: xreed@aggies.ncat.edu | E14: reed.xamora@gmail.com | F14: Personal email | G14: =IF(F14="College/Secondary email:",D14,E14) -> reed.xamora@gmail.com | H14: Charlotte, NC | I14: Analyst | J14: +17048044258 | K14: Female | L14: Fall 2024 | M14: 2027 | N14: North America | O14: N/A | P14: Yes | Q14: Wells Fargo | R14: Charlotte, NC | S14: Corporate Finance | T14: 1 | U14: N/A | V14: N/A | W14: N/A | X14: N/A | Y14: N/A | Z14: N/A | AA14: N/A | AB14: N/A | AC14: N/A | AD14: N/A | AE14: N/A | AF14: N/A | AG14: North Carolina A&T State University | AH14: Greensboro, NC | AI14: HBCU (Historically Black Colleges and Universities) | AJ14: 4 | AK14: Economics (Law) | AL14: 2027 | AM14: MLT, Forte, Greenwood Project | AN14: https://drive.google.com/open?id=1FbdVgS-aPP6RzHZx6vasc8lxS2jTXtx2 | AO14: Investment Banking, Sales and Trading, Private Equity, Asset Management, Venture Capital, Hedge Funds | AP14: Alphine, Bain Capital, Evercore, Goldman Sachs, JP Morgan, KKR, Lazard, Morgan Stanley, Neuberger Berman, PWP, Roark, UBS, Warburg Pincus, Wells Fargo | AS14: Analyst | AT14: Merged on Nov 07, 2025 18:05:16
A15: Chijioke | B15: Achebe | C15: BLK - 22249 | D15: coa13@georgetown.edu | E15: chijioke.achebe@gmail.com | F15: Personal email | G15: =IF(F15="College/Secondary email:",D15,E15) -> chijioke.achebe@gmail.com | H15: West Orange, NJ | I15: Analyst | J15: +19735184496 | K15: Male | L15: Fall 2022 | M15: 2025 | N15: North America | O15: N/A | P15: Yes | Q15: Essex County Prosecutor's Office | R15: West Orange, NJ | S15: Government | T15: N/A | U15: N/A | V15: UBA America | W15: New York, NY | X15: Corporate Banking/Trade Finance | Y15: N/A | Z15: N/A | AA15: Morgan Stanley | AB15: New York, NY | AC15: Public Finance Investment Banking | AD15: 1 | AE15: N/A | AF15: N/A | AG15: Georgetown University | AH15: Washington, DC | AI15: Target | AJ15: 3.36 | AK15: International Politics | AL15: 2025 | AM15: N/A | AN15: https://drive.google.com/open?id=1vBAa5PcfoUUihYPMYN4PSi-xZ6Qq2YNR | AO15: Investment Banking, Sales and Trading, Private Equity, Asset Management, Management Consulting, Hedge Funds | AP15: Morgan Stanley, Goldman Sachs, J.P. Morgan, Bank of America, Citi | AQ15: I'm also very interested in commodity trading. Eventually, I want to invest in infrastructure projects across Africa - mining, railroads, energy, airports, ports, shipping, etc | AS15: Alumni (only select if you are graduated/graduating this year) | AT15: Merged on Nov 07, 2025 18:05:17
A16: Ezinne | B16: Okwesilieze | C16: BLK-24196 | D16: eo6856j@gre.ac.uk | E16: eokwesilieze1@gmail.com | F16: Personal email | G16: =IF(F16="College/Secondary email:",D16,E16) -> eokwesilieze1@gmail.com | H16: Essex | I16: Analyst | J16: +447908100192 | K16: Female | L16: Fall 2024 | M16: 2026 | N16: EMEA | O16: London (EMEA) | P16: If I gain a work visa | Q16: N/A | R16: N/A | S16: N/A | T16: N/A | U16: N/A | V16: Wellcome Trust | W16: Euston, London | X16: Asset/Investment Management | Y16: I wasn’t of the right year yet to get an offer | Z16: N/A | AA16: N/A | AB16: N/A | AC16: N/A | AD16: N/A | AE16: N/A | AF16: N/A | AG16: Medway School of Pharmacy | AH16: Kent | AI16: Non-target | AJ16: 2:1 | AK16: Pharmacy | AL16: 2026 | AM16: SEO (EMEA), Rare Recruitment | AN16: https://drive.google.com/open?id=1rpc33kD4sQfekQWeOLZ2oaP8_AUetpmg | AO16: Private Equity, Asset Management, Venture Capital, Business & Entreprenuership | AP16: Any reputable and inspiring firms | AQ16: After doing an internship in asset management, investment management, and venture capital, I realized that my pharmacy background could be a great fit for these fields. I’m drawn to the idea of having a bigger impact by shaping industries like healthcare, tech, or pharmaceuticals on a larger scale, beyond just working directly with patients. The critical thinking and data analysis skills I’ve developed in pharmacy are highly transferable, and my knowledge of the healthcare industry can help identify investment opportunities in emerging technologies or drug developments. I’m also interested in the entrepreneurial side of these fields, where I could apply my expertise to fund or start innovative companies. Additionally, asset and investment management offer more career variety and growth, with the chance to work across different industries and expand my professional network. Lastly, the potential for higher compensation is an attractive incentive, especially as I look to build long-term financial security while tackling new challenges. Moving into these fields feels like a natural next step where I can leverage my skills, learn new ones, and make a bigger impact. | AS16: Education Pathways (IB, AWM, or PE) | AT16: Merged on Nov 07, 2025 18:05:18
